Workbook

Sheet README
A1: Kaveri Retail Ltd - three-statement model
A3: How to read this workbook
A4: Blue text = a hardcoded input. Every assumption in the model is blue, and blue is the only
A5: font colour you should ever type over.
A6: Black text = a formula. If you type over black text you have broken the model.
A7: Green text = a link to another sheet in this workbook.
A8: Yellow fill = the checks block. It must read zero.
A10: What this is
A11: A complete, balancing three-statement forecast model. Use it as the target to compare your
A12: own build against - not as something to copy. Build yours first, then open this one.
A14: Sheets
A15: Assumptions every forecast driver, with the FY26 actual beside it for comparison
... A36: working capital, and it is the single most common thing juniors get wrong.

Sheet Assumptions
A1: Kaveri Retail Ltd (KVRA) - forecast assumptions
A2: Fiscal year ends 31 March. All amounts in Rs millions unless stated.
A4: Every forecast driver is anchored to what the business actually did in FY26.
A5: If you change an assumption, say why in the note column.
A7: Driver | B7: FY26A | C7: FY27E | D7: FY28E | E7: FY29E | F7: FY30E | G7: FY31E
A8: Revenue growth (%) | B8: =Model!D7 -> 9207 | C8: 0.06 | D8: 0.055 | E8: 0.05 | F8: 0.045 | G8: 0.04
A9: Gross margin (%) | B9: =Model!D11 -> 0.42000652 | C9: 0.42 | D9: 0.42 | E9: 0.421 | F9: 0.421 | G9: 0.422
A10: Operating expenses (% of revenue) | B10: =Model!D14 -> 0.13500597 | C10: 0.285 | D10: 0.285 | E10: 0.284 | F10: 0.284 | G10: 0.283
A11: Depreciation (% of opening net PPE) | B11: =Model!D46 -> 0.08124667 | C11: 0.08 | D11: 0.08 | E11: 0.08 | F11: 0.08 | G11: 0.08
A12: Amortisation (% of opening intangibles) | B12: =Model!D53 -> 0.058823529 | C12: 0.06 | D12: 0.06 | E12: 0.06 | F12: 0.06 | G12: 0.06
A13: Capex (% of revenue) | B13: =Model!D47 -> 3909 | C13: 0.05 | D13: 0.05 | E13: 0.049 | F13: 0.049 | G13: 0.048
A14: Days sales outstanding (DSO) | B14: =Model!D28 -> 30.644618 | C14: 30.6 | D14: 30.6 | E14: 30 | F14: 30 | G14: 30
A15: Days inventory outstanding (DIO) | B15: =Model!D30 -> 76.622659 | C15: 76.6 | D15: 76 | E15: 75 | F15: 75 | G15: 75
A16: Days payable outstanding (DPO) | B16: =Model!D33 -> 51.058989 | C16: 51.1 | D16: 51 | E16: 51 | F16: 51 | G16: 51
A17: Other current assets (% of revenue) | B17: =Model!D35 -> 0.012816335 | C17: 0.0128 | D17: 0.0128 | E17: 0.0128 | F17: 0.0128 | G17: 0.0128
A18: Accrued liabilities (% of revenue) | B18: =Model!D36 -> 0.010209623 | C18: 0.0102 | D18: 0.0102 | E18: 0.0102 | F18: 0.0102 | G18: 0.0102
A19: Deferred revenue (% of revenue) | B19: =Model!D37 -> 0.012816335 | C19: 0.0128 | D19: 0.0128 | E19: 0.0128 | F19: 0.0128 | G19: 0.0128
A20: Interest rate on opening total debt (%) | B20: =Model!D60 -> 0.10056926 | C20: 0.1 | D20: 0.1 | E20: 0.1 | F20: 0.1 | G20: 0.1
A21: Interest earned on opening cash (%) | B21: =Model!D61 -> 2120 | C21: 0.024 | D21: 0.024 | E21: 0.024 | F21: 0.024 | G21: 0.024
A22: Effective tax rate (%) | B22: =Model!D62 -> 0.25 | C22: 0.25 | D22: 0.25 | E22: 0.25 | F22: 0.25 | G22: 0.25
A23: Scheduled debt repayment (Rs m) | B23: 223 | C23: 223 | D23: 223 | E23: 223 | F23: 223 | G23: 223
A24: Dividend payout (% of net income) | B24: 0 | C24: 0 | D24: 0 | E24: 0 | F24: 0 | G24: 0
A26: Blue = you may change it. Green = pulled from the Model sheet's actuals.
A27: Note: interest is charged on OPENING debt, not average debt. That removes the
A28: circular reference entirely, at the cost of a little precision. See Module 14.

Sheet Model
A1: Kaveri Retail Ltd (KVRA) - three-statement model
A2: Rs millions, fiscal years ending 31 March
A3: FY24-FY26 are actuals (blue). FY27-FY31 are formulas, identical across every forecast column.
A5: Fiscal year | B5: FY24A | C5: FY25A | D5: FY26A | E5: FY27E | F5: FY28E | G5: FY29E | H5: FY30E | I5: FY31E
A6: INCOME STATEMENT
A7: Revenue | B7: 8249 | C7: 8671 | D7: 9207 | E7: =D7*(1+Assumptions!C8) -> 9759.42 | F7: =E7*(1+Assumptions!D8) -> 10296.188 | G7: =F7*(1+Assumptions!E8) -> 10810.998 | H7: =G7*(1+Assumptions!F8) -> 11297.492 | I7: =H7*(1+Assumptions!G8) -> 11749.392
A8: Revenue growth (%) | C8: =C7/B7-1 -> 0.051157716 | D8: =D7/C7-1 -> 0.061815246 | E8: =E7/D7-1 -> 0.06 | F8: =F7/E7-1 -> 0.055 | G8: =G7/F7-1 -> 0.05 | H8: =H7/G7-1 -> 0.045 | I8: =I7/H7-1 -> 0.04
A9: Cost of goods sold | B9: 4784 | C9: 5029 | D9: 5340 | E9: =E7*(1-Assumptions!C9) -> 5660.4636 | F9: =F7*(1-Assumptions!D9) -> 5971.7891 | G9: =G7*(1-Assumptions!E9) -> 6259.5676 | H9: =H7*(1-Assumptions!F9) -> 6541.2481 | I9: =I7*(1-Assumptions!G9) -> 6791.1486
A10: Gross profit | B10: =B7-B9 -> 3465 | C10: =C7-C9 -> 3642 | D10: =D7-D9 -> 3867 | E10: =E7-E9 -> 4098.9564 | F10: =F7-F9 -> 4324.399 | G10: =G7-G9 -> 4551.4299 | H10: =H7-H9 -> 4756.2443 | I10: =I7-I9 -> 4958.2435
A11: Gross margin (%) | B11: =B10/B7 -> 0.42005092 | C11: =C10/C7 -> 0.42002076 | D11: =D10/D7 -> 0.42000652 | E11: =E10/E7 -> 0.42 | F11: =F10/F7 -> 0.42 | G11: =G10/G7 -> 0.421 | H11: =H10/H7 -> 0.421 | I11: =I10/I7 -> 0.422
A12: Operating expenses | B12: 2351 | C12: 2471 | D12: 2624 | E12: =E7*Assumptions!C10 -> 2781.4347 | F12: =F7*Assumptions!D10 -> 2934.4136 | G12: =G7*Assumptions!E10 -> 3070.3233 | H12: =H7*Assumptions!F10 -> 3208.4878 | I12: =I7*Assumptions!G10 -> 3325.078
A13: EBITDA | B13: =B10-B12 -> 1114 | C13: =C10-C12 -> 1171 | D13: =D10-D12 -> 1243 | E13: =E10-E12 -> 1317.5217 | F13: =F10-F12 -> 1389.9854 | G13: =G10-G12 -> 1481.1067 | H13: =H10-H12 -> 1547.7565 | I13: =I10-I12 -> 1633.1655
A14: EBITDA margin (%) | B14: =B13/B7 -> 0.13504667 | C14: =C13/C7 -> 0.13504786 | D14: =D13/D7 -> 0.13500597 | E14: =E13/E7 -> 0.135 | F14: =F13/F7 -> 0.135 | G14: =G13/G7 -> 0.137 | H14: =H13/H7 -> 0.137 | I14: =I13/I7 -> 0.139
A15: Depreciation | B15: 284 | C15: 293 | D15: 305 | E15: =E48 -> 312.72 | F15: =F48 -> 326.74008 | G15: =G48 -> 341.78563 | H15: =H48 -> 356.82189 | I15: =I48 -> 372.56231
A16: Amortisation | B16: 8 | C16: 7 | D16: 7 | E16: =E54 -> 6.72 | F16: =F54 -> 6.3168 | G16: =G54 -> 5.937792 | H16: =H54 -> 5.5815245 | I16: =I54 -> 5.246633
A17: EBIT | B17: =B13-B15-B16 -> 822 | C17: =C13-C15-C16 -> 871 | D17: =D13-D15-D16 -> 931 | E17: =E13-E15-E16 -> 998.0817 | F17: =F13-F15-F16 -> 1056.9285 | G17: =G13-G15-G16 -> 1133.3832 | H17: =H13-H15-H16 -> 1185.353 | I17: =I13-I15-I16 -> 1255.3566
A18: Interest expense | B18: 312 | C18: 288 | D18: 265 | E18: =D64*Assumptions!C20 -> 241.2 | F18: =E64*Assumptions!D20 -> 218.9 | G18: =F64*Assumptions!E20 -> 196.6 | H18: =G64*Assumptions!F20 -> 174.3 | I18: =H64*Assumptions!G20 -> 152
A19: Interest income | B19: 82 | C19: 83 | D19: 86 | E19: =D82*Assumptions!C21 -> 87.864 | F19: =E82*Assumptions!D21 -> 92.206328 | G19: =F82*Assumptions!E21 -> 97.962218 | H19: =G82*Assumptions!F21 -> 106.32251 | I19: =H82*Assumptions!G21 -> 115.21002
A20: Profit before tax | B20: =B17-B18+B19 -> 592 | C20: =C17-C18+C19 -> 666 | D20: =D17-D18+D19 -> 752 | E20: =E17-E18+E19 -> 844.7457 | F20: =F17-F18+F19 -> 930.23484 | G20: =G17-G18+G19 -> 1034.7455 | H20: =H17-H18+H19 -> 1117.3756 | I20: =I17-I18+I19 -> 1218.5666
A21: Tax | B21: 148 | C21: 166 | D21: 188 | E21: =MAX(E20,0)*Assumptions!C22 -> 211.18643 | F21: =MAX(F20,0)*Assumptions!D22 -> 232.55871 | G21: =MAX(G20,0)*Assumptions!E22 -> 258.68636 | H21: =MAX(H20,0)*Assumptions!F22 -> 279.34389 | I21: =MAX(I20,0)*Assumptions!G22 -> 304.64164
A22: Net income | B22: =B20-B21 -> 444 | C22: =C20-C21 -> 500 | D22: =D20-D21 -> 564 | E22: =E20-E21 -> 633.55927 | F22: =F20-F21 -> 697.67613 | G22: =G20-G21 -> 776.05909 | H22: =H20-H21 -> 838.03167 | I22: =I20-I21 -> 913.92493
A23: Net margin (%) | B23: =B22/B7 -> 0.053824706 | C23: =C22/C7 -> 0.057663476 | D23: =D22/D7 -> 0.061257739 | E23: =E22/E7 -> 0.064917718 | F23: =F22/F7 -> 0.067760624 | G23: =G22/G7 -> 0.071784226 | H23: =H22/H7 -> 0.074178556 | I23: =I22/I7 -> 0.07778487
A24: Dividends paid | B24: 0 | C24: 0 | D24: 0 | E24: =MAX(E22,0)*Assumptions!C24 -> 0 | F24: =MAX(F22,0)*Assumptions!D24 -> 0 | G24: =MAX(G22,0)*Assumptions!E24 -> 0 | H24: =MAX(H22,0)*Assumptions!F24 -> 0 | I24: =MAX(I22,0)*Assumptions!G24 -> 0
A26: WORKING CAPITAL SCHEDULE
A27: Accounts receivable | B27: 730 | C27: 726 | D27: 773 | E27: =Assumptions!C14/365*E7 -> 818.18699 | F27: =Assumptions!D14/365*F7 -> 863.18728 | G27: =Assumptions!E14/365*G7 -> 888.57514 | H27: =Assumptions!F14/365*H7 -> 928.56102 | I27: =Assumptions!G14/365*I7 -> 965.70346
A28: DSO (days) | B28: =B27/B7*365 -> 32.300885 | C28: =C27/C7*365 -> 30.560489 | D28: =D27/D7*365 -> 30.644618 | E28: =E27/E7*365 -> 30.6 | F28: =F27/F7*365 -> 30.6 | G28: =G27/G7*365 -> 30 | H28: =H27/H7*365 -> 30 | I28: =I27/I7*365 -> 30
A29: Inventory | B29: 1058 | C29: 1053 | D29: 1121 | E29: =Assumptions!C15/365*E9 -> 1187.922 | F29: =Assumptions!D15/365*F9 -> 1243.441 | G29: =Assumptions!E15/365*G9 -> 1286.2125 | H29: =Assumptions!F15/365*H9 -> 1344.0921 | I29: =Assumptions!G15/365*I9 -> 1395.4415
A30: DIO (days) | B30: =B29/B9*365 -> 80.721154 | C30: =C29/C9*365 -> 76.425731 | D30: =D29/D9*365 -> 76.622659 | E30: =E29/E9*365 -> 76.6 | F30: =F29/F9*365 -> 76 | G30: =G29/G9*365 -> 75 | H30: =H29/H9*365 -> 75 | I30: =I29/I9*365 -> 75
A31: Other current assets | B31: 111 | C31: 110 | D31: 118 | E31: =E7*Assumptions!C17 -> 124.92058 | F31: =F7*Assumptions!D17 -> 131.79121 | G31: =G7*Assumptions!E17 -> 138.38077 | H31: =H7*Assumptions!F17 -> 144.6079 | I31: =I7*Assumptions!G17 -> 150.39222
A32: Accounts payable | B32: 705 | C32: 702 | D32: 747 | E32: =Assumptions!C16/365*E9 -> 792.4649 | F32: =Assumptions!D16/365*F9 -> 834.41437 | G32: =Assumptions!E16/365*G9 -> 874.62451 | H32: =Assumptions!F16/365*H9 -> 913.98261 | I32: =Assumptions!G16/365*I9 -> 948.90022
A33: DPO (days) | B33: =B32/B9*365 -> 53.788671 | C33: =C32/C9*365 -> 50.950487 | D33: =D32/D9*365 -> 51.058989 | E33: =E32/E9*365 -> 51.1 | F33: =F32/F9*365 -> 51 | G33: =G32/G9*365 -> 51 | H33: =H32/H9*365 -> 51 | I33: =I32/I9*365 -> 51
A34: Accrued liabilities | B34: 89 | C34: 88 | D34: 94 | E34: =E7*Assumptions!C18 -> 99.546084 | F34: =F7*Assumptions!D18 -> 105.02112 | G34: =G7*Assumptions!E18 -> 110.27217 | H34: =H7*Assumptions!F18 -> 115.23442 | I34: =I7*Assumptions!G18 -> 119.8438
A35: Other current assets (% of revenue) | B35: =B31/B7 -> 0.013456177 | C35: =C31/C7 -> 0.012685965 | D35: =D31/D7 -> 0.012816335 | E35: =E31/E7 -> 0.0128 | F35: =F31/F7 -> 0.0128 | G35: =G31/G7 -> 0.0128 | H35: =H31/H7 -> 0.0128 | I35: =I31/I7 -> 0.0128
A36: Accrued liabilities (% of revenue) | B36: =B34/B7 -> 0.010789187 | C36: =C34/C7 -> 0.010148772 | D36: =D34/D7 -> 0.010209623 | E36: =E34/E7 -> 0.0102 | F36: =F34/F7 -> 0.0102 | G36: =G34/G7 -> 0.0102 | H36: =H34/H7 -> 0.0102 | I36: =I34/I7 -> 0.0102
A37: Deferred revenue (% of revenue) | B37: =B38/B7 -> 0.013456177 | C37: =C38/C7 -> 0.012685965 | D37: =D38/D7 -> 0.012816335 | E37: =E38/E7 -> 0.0128 | F37: =F38/F7 -> 0.0128 | G37: =G38/G7 -> 0.0128 | H37: =H38/H7 -> 0.0128 | I37: =I38/I7 -> 0.0128
A38: Deferred revenue | B38: 111 | C38: 110 | D38: 118 | E38: =E7*Assumptions!C19 -> 124.92058 | F38: =F7*Assumptions!D19 -> 131.79121 | G38: =G7*Assumptions!E19 -> 138.38077 | H38: =H7*Assumptions!F19 -> 144.6079 | I38: =I7*Assumptions!G19 -> 150.39222
A39: Net working capital | B39: =B27+B29+B31-B32-B34-B38 -> 994 | C39: =C27+C29+C31-C32-C34-C38 -> 989 | D39: =D27+D29+D31-D32-D34-D38 -> 1053 | E39: =E27+E29+E31-E32-E34-E38 -> 1114.098 | F39: =F27+F29+F31-F32-F34-F38 -> 1167.1928 | G39: =G27+G29+G31-G32-G34-G38 -> 1189.891 | H39: =H27+H29+H31-H32-H34-H38 -> 1243.4361 | I39: =I27+I29+I31-I32-I34-I38 -> 1292.4009
A40: Change in net working capital | C40: =C39-B39 -> -5 | D40: =D39-C39 -> 64 | E40: =E39-D39 -> 61.097954 | F40: =F39-E39 -> 53.094854 | G40: =G39-F39 -> 22.698158 | H40: =H39-G39 -> 53.545093 | I40: =I39-H39 -> 48.96488
A41: Cash impact of working capital | C41: =-C40 -> 5 | D41: =-D40 -> -64 | E41: =-E40 -> -61.097954 | F41: =-F40 -> -53.094854 | G41: =-G40 -> -22.698158 | H41: =-H40 -> -53.545093 | I41: =-I40 -> -48.96488
A43: FIXED ASSET AND INTANGIBLE SCHEDULES
...
