Workbook

Sheet README
A1: Kaveri Retail Ltd - DCF and comparable companies
A3: How to read this workbook
A4: Blue text = a hardcoded input. Every assumption in the model is blue, and blue is the only
A5: font colour you should ever type over.
A6: Black text = a formula. If you type over black text you have broken the model.
A7: Green text = a link to another sheet in this workbook.
A8: Yellow fill = the checks block. It must read zero.
A10: What this is
A11: The valuation half of the reference set: a discounted cash flow, two sensitivity grids and a
A12: comparable companies table. It follows on from workbook 01.
A14: Sheets
A15: Assumptions WACC build and the valuation inputs, each with its source
... A40: actually asks you.

Sheet Assumptions
A1: Kaveri Retail Ltd (KVRA) - valuation assumptions
A3: Input | B3: Value | C3: Where it comes from
A4: Risk-free rate | B4: 0.07 | C4: 10-year government bond yield
A5: Equity risk premium | B5: 0.06 | C5: Long-run excess return of equities over bonds
A6: Levered beta | B6: 1.1 | C6: Peer average, re-levered to this capital structure
A7: Pre-tax cost of debt | B7: 0.1 | C7: Interest expense over average debt, Model!D60
A8: Tax rate | B8: 0.25 | C8: Effective rate, Model!D62
A9: Market capitalisation (Rs m) | B9: 13048 | C9: 87.17m shares x Rs 149.69 at 31-Mar-2026
A10: Total debt (Rs m) | B10: 2412 | C10: Balance sheet at 31-Mar-2026
A11: Cash (Rs m) | B11: 3661 | C11: Balance sheet at 31-Mar-2026
A12: Terminal growth rate | B12: 0.04 | C12: At or below long-run nominal GDP growth
A13: Exit EBITDA multiple | B13: 9 | C13: Peer median, see Comps sheet
A14: Diluted shares (m) | B14: 87.17 | C14: dim_company.shares_out_m
A15: Current share price (Rs) | B15: 149.6865 | C15: Close on 31-Mar-2026
A17: WACC BUILD
A18: Cost of equity | B18: =B4+B6*B5 -> 0.136 | C18: risk-free + beta x equity risk premium
A19: After-tax cost of debt | B19: =B7*(1-B8) -> 0.075
A20: Net debt | B20: =B10-B11 -> -1249
A21: Enterprise value (market) | B21: =B9+B20 -> 11799
A22: Equity weight | B22: =B9/(B9+B10) -> 0.84398448 | C22: market values, not book values
A23: Debt weight | B23: =B10/(B9+B10) -> 0.15601552
A24: WACC | B24: =B22*B18+B23*B19 -> 0.12648305
A26: Note: this company holds more cash than debt, so net debt is negative and the
A27: equity bridge ADDS the net cash back. Getting that sign wrong is a classic error.

Sheet DCF
A1: Kaveri Retail Ltd - discounted cash flow
A2: Rs millions. Unlevered free cash flow, mid-year discounting.
A4: Fiscal year | B4: FY27E | C4: FY28E | D4: FY29E | E4: FY30E | F4: FY31E
A5: UNLEVERED FREE CASH FLOW
A6: EBITDA | B6: 1317.5 | C6: 1390 | D6: 1481.1 | E6: 1547.8 | F6: 1633.2 | G6: from Model!E13:I13
A7: EBIT | B7: 998.1 | C7: 1056.9 | D7: 1133.4 | E7: 1185.4 | F7: 1255.4 | G7: from Model!E17:I17
A8: Tax on EBIT | B8: =-B7*Assumptions!$B$8 -> -249.525 | C8: =-C7*Assumptions!$B$8 -> -264.225 | D8: =-D7*Assumptions!$B$8 -> -283.35 | E8: =-E7*Assumptions!$B$8 -> -296.35 | F8: =-F7*Assumptions!$B$8 -> -313.85
A9: NOPAT | B9: =B7+B8 -> 748.575 | C9: =C7+C8 -> 792.675 | D9: =D7+D8 -> 850.05 | E9: =E7+E8 -> 889.05 | F9: =F7+F8 -> 941.55
A10: Add: depreciation and amortisation | B10: 319.4 | C10: 333 | D10: 347.7 | E10: 362.4 | F10: 377.8 | G10: from Model!E15:I15 + E16:I16
A11: Less: capital expenditure | B11: 488 | C11: 514.8 | D11: 529.7 | E11: 553.6 | F11: 564 | G11: from Model!E45:I45
A12: Capex (shown as an outflow) | B12: =-B11 -> -488 | C12: =-C11 -> -514.8 | D12: =-D11 -> -529.7 | E12: =-E11 -> -553.6 | F12: =-F11 -> -564
A13: Change in working capital (cash impact) | B13: -61.1 | C13: -53.1 | D13: -22.7 | E13: -53.5 | F13: -49 | G13: from Model!E41:I41
A14: Unlevered free cash flow | B14: =B9+B10+B12+B13 -> 518.875 | C14: =C9+C10+C12+C13 -> 557.775 | D14: =D9+D10+D12+D13 -> 645.35 | E14: =E9+E10+E12+E13 -> 644.35 | F14: =F9+F10+F12+F13 -> 706.35
A16: DISCOUNTING
A17: Discount period (mid-year) | B17: 0.5 | C17: 1.5 | D17: 2.5 | E17: 3.5 | F17: 4.5
A18: Discount factor | B18: =1/(1+Assumptions!$B$24)^B17 -> 0.94218822 | C18: =1/(1+Assumptions!$B$24)^C17 -> 0.83639804 | D18: =1/(1+Assumptions!$B$24)^D17 -> 0.74248613 | E18: =1/(1+Assumptions!$B$24)^E17 -> 0.65911877 | F18: =1/(1+Assumptions!$B$24)^F17 -> 0.58511202
A19: Present value of free cash flow | B19: =B14*B18 -> 488.87791 | C19: =C14*C18 -> 466.52192 | D19: =D14*D18 -> 479.16342 | E19: =E14*E18 -> 424.70318 | F19: =F14*F18 -> 413.29387
A20: Sum of present values, forecast period | B20: =SUM(B19:F19) -> 2272.5603
A22: TERMINAL VALUE
A23: Terminal discount period | B23: =F17+0.5 -> 5 | C23: end of the final year, not mid-year
A24: Method 1: Gordon growth
A25: Terminal value | B25: =$B$33*(1+Assumptions!$B$12)/(Assumptions!$B$24-Assumptions!$B$12) -> 10733.34
A26: Present value of terminal value | B26: =B25/(1+Assumptions!$B$24)^B23 -> 5917.1362
A27: Implied exit EBITDA multiple | B27: =B25/F6 -> 6.5719691
A28: Method 2: Exit multiple
A29: Terminal value | B29: =F6*Assumptions!$B$13 -> 14698.8
A30: Present value of terminal value | B30: =B29/(1+Assumptions!$B$24)^B23 -> 8103.2375
A31: Implied terminal growth rate | B31: =(Assumptions!$B$24*B29-F14)/(B29+F14) -> 0.074832059
A32: Normalised terminal capex (x depreciation) | B32: 1 | C32: in perpetuity a business only needs to replace what wears out
A33: Normalised terminal free cash flow | B33: =F9+F10-F10*$B$32+F13 -> 892.55 | C33: NOPAT + D&A - normalised capex + working capital
A34: If those two implied numbers disagree wildly, one of your assumptions is wrong.
A40: VALUATION (Gordon growth method)
A41: Present value of forecast cash flows | B41: =B20 -> 2272.5603
A42: Present value of terminal value | B42: =B26 -> 5917.1362
A43: Enterprise value | B43: =B41+B42 -> 8189.6965
A44: Terminal value as % of enterprise value | B44: =B42/B43 -> 0.72250983 | C44: the honesty check - how much of your answer is a guess about year 6 onwards?
A45: Implied EV / FY26 EBITDA | B45: =B43/1243 -> 6.5886537 | C45: compare this with the peer median on the Comps sheet
A46: Less: net debt (add back net cash) | B46: =-Assumptions!B20 -> 1249
A47: Equity value | B47: =B43+B46 -> 9438.6965
A48: Diluted shares (m) | B48: =Assumptions!B14 -> 87.17
...

Sheet Sensitivity
A1: Sensitivity - value per share (Rs)
A2: Every cell recomputes the whole valuation. Nothing here is pasted.
A4: WACC (down) vs terminal growth (across)
A5: WACC | B5: 0.03 | C5: 0.035 | D5: 0.04 | E5: 0.045 | F5: 0.05
A6: 0.08 | B6: =(SUMPRODUCT(DCF!$B$14:$F$14,(1+$A6)^-DCF!$B$17:$F$17)+DCF!$F$14*(1+B$5)/($A6-B$5)/(1+$A6)^DCF!$B$23-Assumptions!$B$20)/Assumptions!$B$14 -> 156.84834 | C6: =(SUMPRODUCT(DCF!$B$14:$F$14,(1+$A6)^-DCF!$B$17:$F$17)+DCF!$F$14*(1+C$5)/($A6-C$5)/(1+$A6)^DCF!$B$23-Assumptions!$B$20)/Assumptions!$B$14 -> 170.084 | D6: =(SUMPRODUCT(DCF!$B$14:$F$14,(1+$A6)^-DCF!$B$17:$F$17)+DCF!$F$14*(1+D$5)/($A6-D$5)/(1+$A6)^DCF!$B$23-Assumptions!$B$20)/Assumptions!$B$14 -> 186.62856 | E6: =(SUMPRODUCT(DCF!$B$14:$F$14,(1+$A6)^-DCF!$B$17:$F$17)+DCF!$F$14*(1+E$5)/($A6-E$5)/(1+$A6)^DCF!$B$23-Assumptions!$B$20)/Assumptions!$B$14 -> 207.90015 | F6: =(SUMPRODUCT(DCF!$B$14:$F$14,(1+$A6)^-DCF!$B$17:$F$17)+DCF!$F$14*(1+F$5)/($A6-F$5)/(1+$A6)^DCF!$B$23-Assumptions!$B$20)/Assumptions!$B$14 -> 236.26226
A7: 0.09 | B7: =(SUMPRODUCT(DCF!$B$14:$F$14,(1+$A7)^-DCF!$B$17:$F$17)+DCF!$F$14*(1+B$5)/($A7-B$5)/(1+$A7)^DCF!$B$23-Assumptions!$B$20)/Assumptions!$B$14 -> 132.99442 | C7: =(SUMPRODUCT(DCF!$B$14:$F$14,(1+$A7)^-DCF!$B$17:$F$17)+DCF!$F$14*(1+C$5)/($A7-C$5)/(1+$A7)^DCF!$B$23-Assumptions!$B$20)/Assumptions!$B$14 -> 141.69209 | D7: =(SUMPRODUCT(DCF!$B$14:$F$14,(1+$A7)^-DCF!$B$17:$F$17)+DCF!$F$14*(1+D$5)/($A7-D$5)/(1+$A7)^DCF!$B$23-Assumptions!$B$20)/Assumptions!$B$14 -> 152.12929 | E7: =(SUMPRODUCT(DCF!$B$14:$F$14,(1+$A7)^-DCF!$B$17:$F$17)+DCF!$F$14*(1+E$5)/($A7-E$5)/(1+$A7)^DCF!$B$23-Assumptions!$B$20)/Assumptions!$B$14 -> 164.88588 | F7: =(SUMPRODUCT(DCF!$B$14:$F$14,(1+$A7)^-DCF!$B$17:$F$17)+DCF!$F$14*(1+F$5)/($A7-F$5)/(1+$A7)^DCF!$B$23-Assumptions!$B$20)/Assumptions!$B$14 -> 180.83161
A8: 0.1 | B8: =(SUMPRODUCT(DCF!$B$14:$F$14,(1+$A8)^-DCF!$B$17:$F$17)+DCF!$F$14*(1+B$5)/($A8-B$5)/(1+$A8)^DCF!$B$23-Assumptions!$B$20)/Assumptions!$B$14 -> 115.98952 | C8: =(SUMPRODUCT(DCF!$B$14:$F$14,(1+$A8)^-DCF!$B$17:$F$17)+DCF!$F$14*(1+C$5)/($A8-C$5)/(1+$A8)^DCF!$B$23-Assumptions!$B$20)/Assumptions!$B$14 -> 122.07144 | D8: =(SUMPRODUCT(DCF!$B$14:$F$14,(1+$A8)^-DCF!$B$17:$F$17)+DCF!$F$14*(1+D$5)/($A8-D$5)/(1+$A8)^DCF!$B$23-Assumptions!$B$20)/Assumptions!$B$14 -> 129.16701 | E8: =(SUMPRODUCT(DCF!$B$14:$F$14,(1+$A8)^-DCF!$B$17:$F$17)+DCF!$F$14*(1+E$5)/($A8-E$5)/(1+$A8)^DCF!$B$23-Assumptions!$B$20)/Assumptions!$B$14 -> 137.55269 | F8: =(SUMPRODUCT(DCF!$B$14:$F$14,(1+$A8)^-DCF!$B$17:$F$17)+DCF!$F$14*(1+F$5)/($A8-F$5)/(1+$A8)^DCF!$B$23-Assumptions!$B$20)/Assumptions!$B$14 -> 147.6155
A9: 0.11 | B9: =(SUMPRODUCT(DCF!$B$14:$F$14,(1+$A9)^-DCF!$B$17:$F$17)+DCF!$F$14*(1+B$5)/($A9-B$5)/(1+$A9)^DCF!$B$23-Assumptions!$B$20)/Assumptions!$B$14 -> 103.26285 | C9: =(SUMPRODUCT(DCF!$B$14:$F$14,(1+$A9)^-DCF!$B$17:$F$17)+DCF!$F$14*(1+C$5)/($A9-C$5)/(1+$A9)^DCF!$B$23-Assumptions!$B$20)/Assumptions!$B$14 -> 107.711 | D9: =(SUMPRODUCT(DCF!$B$14:$F$14,(1+$A9)^-DCF!$B$17:$F$17)+DCF!$F$14*(1+D$5)/($A9-D$5)/(1+$A9)^DCF!$B$23-Assumptions!$B$20)/Assumptions!$B$14 -> 112.79461 | E9: =(SUMPRODUCT(DCF!$B$14:$F$14,(1+$A9)^-DCF!$B$17:$F$17)+DCF!$F$14*(1+E$5)/($A9-E$5)/(1+$A9)^DCF!$B$23-Assumptions!$B$20)/Assumptions!$B$14 -> 118.6603 | F9: =(SUMPRODUCT(DCF!$B$14:$F$14,(1+$A9)^-DCF!$B$17:$F$17)+DCF!$F$14*(1+F$5)/($A9-F$5)/(1+$A9)^DCF!$B$23-Assumptions!$B$20)/Assumptions!$B$14 -> 125.50362
A10: 0.12 | B10: =(SUMPRODUCT(DCF!$B$14:$F$14,(1+$A10)^-DCF!$B$17:$F$17)+DCF!$F$14*(1+B$5)/($A10-B$5)/(1+$A10)^DCF!$B$23-Assumptions!$B$20)/Assumptions!$B$14 -> 93.386387 | C10: =(SUMPRODUCT(DCF!$B$14:$F$14,(1+$A10)^-DCF!$B$17:$F$17)+DCF!$F$14*(1+C$5)/($A10-C$5)/(1+$A10)^DCF!$B$23-Assumptions!$B$20)/Assumptions!$B$14 -> 96.752196 | D10: =(SUMPRODUCT(DCF!$B$14:$F$14,(1+$A10)^-DCF!$B$17:$F$17)+DCF!$F$14*(1+D$5)/($A10-D$5)/(1+$A10)^DCF!$B$23-Assumptions!$B$20)/Assumptions!$B$14 -> 100.53873 | E10: =(SUMPRODUCT(DCF!$B$14:$F$14,(1+$A10)^-DCF!$B$17:$F$17)+DCF!$F$14*(1+E$5)/($A10-E$5)/(1+$A10)^DCF!$B$23-Assumptions!$B$20)/Assumptions!$B$14 -> 104.83014 | F10: =(SUMPRODUCT(DCF!$B$14:$F$14,(1+$A10)^-DCF!$B$17:$F$17)+DCF!$F$14*(1+F$5)/($A10-F$5)/(1+$A10)^DCF!$B$23-Assumptions!$B$20)/Assumptions!$B$14 -> 109.7346
A11: 0.13 | B11: =(SUMPRODUCT(DCF!$B$14:$F$14,(1+$A11)^-DCF!$B$17:$F$17)+DCF!$F$14*(1+B$5)/($A11-B$5)/(1+$A11)^DCF!$B$23-Assumptions!$B$20)/Assumptions!$B$14 -> 85.503454 | C11: =(SUMPRODUCT(DCF!$B$14:$F$14,(1+$A11)^-DCF!$B$17:$F$17)+DCF!$F$14*(1+C$5)/($A11-C$5)/(1+$A11)^DCF!$B$23-Assumptions!$B$20)/Assumptions!$B$14 -> 88.119139 | D11: =(SUMPRODUCT(DCF!$B$14:$F$14,(1+$A11)^-DCF!$B$17:$F$17)+DCF!$F$14*(1+D$5)/($A11-D$5)/(1+$A11)^DCF!$B$23-Assumptions!$B$20)/Assumptions!$B$14 -> 91.025456 | E11: =(SUMPRODUCT(DCF!$B$14:$F$14,(1+$A11)^-DCF!$B$17:$F$17)+DCF!$F$14*(1+E$5)/($A11-E$5)/(1+$A11)^DCF!$B$23-Assumptions!$B$20)/Assumptions!$B$14 -> 94.273693 | F11: =(SUMPRODUCT(DCF!$B$14:$F$14,(1+$A11)^-DCF!$B$17:$F$17)+DCF!$F$14*(1+F$5)/($A11-F$5)/(1+$A11)^DCF!$B$23-Assumptions!$B$20)/Assumptions!$B$14 -> 97.92796
A12: 0.14 | B12: =(SUMPRODUCT(DCF!$B$14:$F$14,(1+$A12)^-DCF!$B$17:$F$17)+DCF!$F$14*(1+B$5)/($A12-B$5)/(1+$A12)^DCF!$B$23-Assumptions!$B$20)/Assumptions!$B$14 -> 79.069013 | C12: =(SUMPRODUCT(DCF!$B$14:$F$14,(1+$A12)^-DCF!$B$17:$F$17)+DCF!$F$14*(1+C$5)/($A12-C$5)/(1+$A12)^DCF!$B$23-Assumptions!$B$20)/Assumptions!$B$14 -> 81.145941 | D12: =(SUMPRODUCT(DCF!$B$14:$F$14,(1+$A12)^-DCF!$B$17:$F$17)+DCF!$F$14*(1+D$5)/($A12-D$5)/(1+$A12)^DCF!$B$23-Assumptions!$B$20)/Assumptions!$B$14 -> 83.430562 | E12: =(SUMPRODUCT(DCF!$B$14:$F$14,(1+$A12)^-DCF!$B$17:$F$17)+DCF!$F$14*(1+E$5)/($A12-E$5)/(1+$A12)^DCF!$B$23-Assumptions!$B$20)/Assumptions!$B$14 -> 85.95567 | F12: =(SUMPRODUCT(DCF!$B$14:$F$14,(1+$A12)^-DCF!$B$17:$F$17)+DCF!$F$14*(1+F$5)/($A12-F$5)/(1+$A12)^DCF!$B$23-Assumptions!$B$20)/Assumptions!$B$14 -> 88.761345
A15: WACC (down) vs exit EBITDA multiple (across)
A16: WACC | B16: 7 | C16: 8 | D16: 9 | E16: 10 | F16: 11
A17: 0.08 | B17: =(SUMPRODUCT(DCF!$B$14:$F$14,(1+$A17)^-DCF!$B$17:$F$17)+DCF!$F$6*B$16/(1+$A17)^DCF!$B$23-Assumptions!$B$20)/Assumptions!$B$14 -> 132.50123 | C17: =(SUMPRODUCT(DCF!$B$14:$F$14,(1+$A17)^-DCF!$B$17:$F$17)+DCF!$F$6*C$16/(1+$A17)^DCF!$B$23-Assumptions!$B$20)/Assumptions!$B$14 -> 145.25251 | D17: =(SUMPRODUCT(DCF!$B$14:$F$14,(1+$A17)^-DCF!$B$17:$F$17)+DCF!$F$6*D$16/(1+$A17)^DCF!$B$23-Assumptions!$B$20)/Assumptions!$B$14 -> 158.00378 | E17: =(SUMPRODUCT(DCF!$B$14:$F$14,(1+$A17)^-DCF!$B$17:$F$17)+DCF!$F$6*E$16/(1+$A17)^DCF!$B$23-Assumptions!$B$20)/Assumptions!$B$14 -> 170.75505 | F17: =(SUMPRODUCT(DCF!$B$14:$F$14,(1+$A17)^-DCF!$B$17:$F$17)+DCF!$F$6*F$16/(1+$A17)^DCF!$B$23-Assumptions!$B$20)/Assumptions!$B$14 -> 183.50633
A18: 0.09 | B18: =(SUMPRODUCT(DCF!$B$14:$F$14,(1+$A18)^-DCF!$B$17:$F$17)+DCF!$F$6*B$16/(1+$A18)^DCF!$B$23-Assumptions!$B$20)/Assumptions!$B$14 -> 127.82542 | C18: =(SUMPRODUCT(DCF!$B$14:$F$14,(1+$A18)^-DCF!$B$17:$F$17)+DCF!$F$6*C$16/(1+$A18)^DCF!$B$23-Assumptions!$B$20)/Assumptions!$B$14 -> 140.00241 | D18: =(SUMPRODUCT(DCF!$B$14:$F$14,(1+$A18)^-DCF!$B$17:$F$17)+DCF!$F$6*D$16/(1+$A18)^DCF!$B$23-Assumptions!$B$20)/Assumptions!$B$14 -> 152.1794 | E18: =(SUMPRODUCT(DCF!$B$14:$F$14,(1+$A18)^-DCF!$B$17:$F$17)+DCF!$F$6*E$16/(1+$A18)^DCF!$B$23-Assumptions!$B$20)/Assumptions!$B$14 -> 164.35639 | F18: =(SUMPRODUCT(DCF!$B$14:$F$14,(1+$A18)^-DCF!$B$17:$F$17)+DCF!$F$6*F$16/(1+$A18)^DCF!$B$23-Assumptions!$B$20)/Assumptions!$B$14 -> 176.53337
A19: 0.1 | B19: =(SUMPRODUCT(DCF!$B$14:$F$14,(1+$A19)^-DCF!$B$17:$F$17)+DCF!$F$6*B$16/(1+$A19)^DCF!$B$23-Assumptions!$B$20)/Assumptions!$B$14 -> 123.39017 | C19: =(SUMPRODUCT(DCF!$B$14:$F$14,(1+$A19)^-DCF!$B$17:$F$17)+DCF!$F$6*C$16/(1+$A19)^DCF!$B$23-Assumptions!$B$20)/Assumptions!$B$14 -> 135.02363 | D19: =(SUMPRODUCT(DCF!$B$14:$F$14,(1+$A19)^-DCF!$B$17:$F$17)+DCF!$F$6*D$16/(1+$A19)^DCF!$B$23-Assumptions!$B$20)/Assumptions!$B$14 -> 146.65709 | E19: =(SUMPRODUCT(DCF!$B$14:$F$14,(1+$A19)^-DCF!$B$17:$F$17)+DCF!$F$6*E$16/(1+$A19)^DCF!$B$23-Assumptions!$B$20)/Assumptions!$B$14 -> 158.29055 | F19: =(SUMPRODUCT(DCF!$B$14:$F$14,(1+$A19)^-DCF!$B$17:$F$17)+DCF!$F$6*F$16/(1+$A19)^DCF!$B$23-Assumptions!$B$20)/Assumptions!$B$14 -> 169.92401
A20: 0.11 | B20: =(SUMPRODUCT(DCF!$B$14:$F$14,(1+$A20)^-DCF!$B$17:$F$17)+DCF!$F$6*B$16/(1+$A20)^DCF!$B$23-Assumptions!$B$20)/Assumptions!$B$14 -> 119.18088 | C20: =(SUMPRODUCT(DCF!$B$14:$F$14,(1+$A20)^-DCF!$B$17:$F$17)+DCF!$F$6*C$16/(1+$A20)^DCF!$B$23-Assumptions!$B$20)/Assumptions!$B$14 -> 130.29967 | D20: =(SUMPRODUCT(DCF!$B$14:$F$14,(1+$A20)^-DCF!$B$17:$F$17)+DCF!$F$6*D$16/(1+$A20)^DCF!$B$23-Assumptions!$B$20)/Assumptions!$B$14 -> 141.41845 | E20: =(SUMPRODUCT(DCF!$B$14:$F$14,(1+$A20)^-DCF!$B$17:$F$17)+DCF!$F$6*E$16/(1+$A20)^DCF!$B$23-Assumptions!$B$20)/Assumptions!$B$14 -> 152.53724 | F20: =(SUMPRODUCT(DCF!$B$14:$F$14,(1+$A20)^-DCF!$B$17:$F$17)+DCF!$F$6*F$16/(1+$A20)^DCF!$B$23-Assumptions!$B$20)/Assumptions!$B$14 -> 163.65603
A21: 0.12 | B21: =(SUMPRODUCT(DCF!$B$14:$F$14,(1+$A21)^-DCF!$B$17:$F$17)+DCF!$F$6*B$16/(1+$A21)^DCF!$B$23-Assumptions!$B$20)/Assumptions!$B$14 -> 115.18397 | C21: =(SUMPRODUCT(DCF!$B$14:$F$14,(1+$A21)^-DCF!$B$17:$F$17)+DCF!$F$6*C$16/(1+$A21)^DCF!$B$23-Assumptions!$B$20)/Assumptions!$B$14 -> 125.81517 | D21: =(SUMPRODUCT(DCF!$B$14:$F$14,(1+$A21)^-DCF!$B$17:$F$17)+DCF!$F$6*D$16/(1+$A21)^DCF!$B$23-Assumptions!$B$20)/Assumptions!$B$14 -> 136.44636 | E21: =(SUMPRODUCT(DCF!$B$14:$F$14,(1+$A21)^-DCF!$B$17:$F$17)+DCF!$F$6*E$16/(1+$A21)^DCF!$B$23-Assumptions!$B$20)/Assumptions!$B$14 -> 147.07756 | F21: =(SUMPRODUCT(DCF!$B$14:$F$14,(1+$A21)^-DCF!$B$17:$F$17)+DCF!$F$6*F$16/(1+$A21)^DCF!$B$23-Assumptions!$B$20)/Assumptions!$B$14 -> 157.70876
A22: 0.13 | B22: =(SUMPRODUCT(DCF!$B$14:$F$14,(1+$A22)^-DCF!$B$17:$F$17)+DCF!$F$6*B$16/(1+$A22)^DCF!$B$23-Assumptions!$B$20)/Assumptions!$B$14 -> 111.38679 | C22: =(SUMPRODUCT(DCF!$B$14:$F$14,(1+$A22)^-DCF!$B$17:$F$17)+DCF!$F$6*C$16/(1+$A22)^DCF!$B$23-Assumptions!$B$20)/Assumptions!$B$14 -> 121.55583 | D22: =(SUMPRODUCT(DCF!$B$14:$F$14,(1+$A22)^-DCF!$B$17:$F$17)+DCF!$F$6*D$16/(1+$A22)^DCF!$B$23-Assumptions!$B$20)/Assumptions!$B$14 -> 131.72488 | E22: =(SUMPRODUCT(DCF!$B$14:$F$14,(1+$A22)^-DCF!$B$17:$F$17)+DCF!$F$6*E$16/(1+$A22)^DCF!$B$23-Assumptions!$B$20)/Assumptions!$B$14 -> 141.89392 | F22: =(SUMPRODUCT(DCF!$B$14:$F$14,(1+$A22)^-DCF!$B$17:$F$17)+DCF!$F$6*F$16/(1+$A22)^DCF!$B$23-Assumptions!$B$20)/Assumptions!$B$14 -> 152.06296
A23: 0.14 | B23: =(SUMPRODUCT(DCF!$B$14:$F$14,(1+$A23)^-DCF!$B$17:$F$17)+DCF!$F$6*B$16/(1+$A23)^DCF!$B$23-Assumptions!$B$20)/Assumptions!$B$14 -> 107.77755 | C23: =(SUMPRODUCT(DCF!$B$14:$F$14,(1+$A23)^-DCF!$B$17:$F$17)+DCF!$F$6*C$16/(1+$A23)^DCF!$B$23-Assumptions!$B$20)/Assumptions!$B$14 -> 117.50834 | D23: =(SUMPRODUCT(DCF!$B$14:$F$14,(1+$A23)^-DCF!$B$17:$F$17)+DCF!$F$6*D$16/(1+$A23)^DCF!$B$23-Assumptions!$B$20)/Assumptions!$B$14 -> 127.23913 | E23: =(SUMPRODUCT(DCF!$B$14:$F$14,(1+$A23)^-DCF!$B$17:$F$17)+DCF!$F$6*E$16/(1+$A23)^DCF!$B$23-Assumptions!$B$20)/Assumptions!$B$14 -> 136.96992 | F23: =(SUMPRODUCT(DCF!$B$14:$F$14,(1+$A23)^-DCF!$B$17:$F$17)+DCF!$F$6*F$16/(1+$A23)^DCF!$B$23-Assumptions!$B$20)/Assumptions!$B$14 -> 146.70071
A26: Read these as a range, not a point. A DCF gives you a region of plausible
A27: values; anyone quoting a single number to two decimal places is overselling.

Sheet Comps
A1: Comparable companies - LTM to 31 March 2026
A2: Rs millions except per-share and multiples. Blue = input, black = calculated.
A4: Ticker | B4: Company | C4: Sector | D4: LTM revenue | E4: LTM EBITDA | F4: LTM EBIT | G4: LTM net income | H4: Shares (m) | I4: Price (Rs) | J4: Gross debt | K4: Cash | L4: Rev growth % | M4: Market cap | N4: Net debt | O4: Enterprise value | P4: EV/Revenue | Q4: EV/EBITDA | R4: EV/EBIT | S4: P/E | T4: EBITDA margin
A5: ZNTH | B5: Zenith Telecom Ltd | C5: Communication Services | D5: 13787 | E5: 3791 | F5: 2327 | G5: 1372 | H5: 88.48 | I5: 272.6698 | J5: 5997 | K5: 4598 | L5: 0.066 | M5: =H5*I5 -> 24125.824 | N5: =J5-K5 -> 1399 | O5: =M5+N5 -> 25524.824 | P5: =IF(D5>0,O5/D5,"nm") -> 1.851369 | Q5: =IF(E5>0,O5/E5,"nm") -> 6.7330055 | R5: =IF(F5>0,O5/F5,"nm") -> 10.968983 | S5: =IF(G5>0,M5/G5,"nm") -> 17.58442 | T5: =E5/D5 -> 0.27496917
A6: BHMT | B6: Bhima Motors Ltd | C6: Consumer Discretionary | D6: 14186 | E6: 1915 | F6: 1388 | G6: 619 | H6: 184.6 | I6: 78.2831 | J6: 6753 | K6: 5930 | L6: 0.082 | M6: =H6*I6 -> 14451.06 | N6: =J6-K6 -> 823 | O6: =M6+N6 -> 15274.06 | P6: =IF(D6>0,O6/D6,"nm") -> 1.0766996 | Q6: =IF(E6>0,O6/E6,"nm") -> 7.9760106 | R6: =IF(F6>0,O6/F6,"nm") -> 11.004366 | S6: =IF(G6>0,M6/G6,"nm") -> 23.345816 | T6: =E6/D6 -> 0.13499225
A7: KVRA | B7: Kaveri Retail Ltd | C7: Consumer Discretionary | D7: 9207 | E7: 1243 | F7: 931 | G7: 564 | H7: 87.17 | I7: 149.6865 | J7: 2412 | K7: 3661 | L7: 0.062 | M7: =H7*I7 -> 13048.172 | N7: =J7-K7 -> -1249 | O7: =M7+N7 -> 11799.172 | P7: =IF(D7>0,O7/D7,"nm") -> 1.2815436 | Q7: =IF(E7>0,O7/E7,"nm") -> 9.4924957 | R7: =IF(F7>0,O7/F7,"nm") -> 12.673654 | S7: =IF(G7>0,M7/G7,"nm") -> 23.135057 | T7: =E7/D7 -> 0.13500597
A8: NLSP | B8: Nilgiri Spice Foods Ltd | C8: Consumer Staples | D8: 14632 | E8: 1975 | F8: 1357 | G8: 579 | H8: 136.01 | I8: 138.0447 | J8: 6488 | K8: 3078 | L8: 0.061 | M8: =H8*I8 -> 18775.46 | N8: =J8-K8 -> 3410 | O8: =M8+N8 -> 22185.46 | P8: =IF(D8>0,O8/D8,"nm") -> 1.5162288 | Q8: =IF(E8>0,O8/E8,"nm") -> 11.233144 | R8: =IF(F8>0,O8/F8,"nm") -> 16.348902 | S8: =IF(G8>0,M8/G8,"nm") -> 32.427391 | T8: =E8/D8 -> 0.13497813
A9: PLMT | B9: Palmetto Grocers Inc | C9: Consumer Staples | D9: 4666 | E9: 630 | F9: 430 | G9: 140 | H9: 32.96 | I9: 133.2541 | J9: 2514 | K9: 853 | L9: 0.065 | M9: =H9*I9 -> 4392.0551 | N9: =J9-K9 -> 1661 | O9: =M9+N9 -> 6053.0551 | P9: =IF(D9>0,O9/D9,"nm") -> 1.2972686 | Q9: =IF(E9>0,O9/E9,"nm") -> 9.608024 | R9: =IF(F9>0,O9/F9,"nm") -> 14.076872 | S9: =IF(G9>0,M9/G9,"nm") -> 31.371822 | T9: =E9/D9 -> 0.13501929
A10: FRNC | B10: Frontier Energy Corp | C10: Energy | D10: 6231 | E10: 1090 | F10: 512 | G10: 223 | H10: 10.71 | I10: 222.8097 | J10: 3221 | K10: 2851 | L10: 0.027 | M10: =H10*I10 -> 2386.2919 | N10: =J10-K10 -> 370 | O10: =M10+N10 -> 2756.2919 | P10: =IF(D10>0,O10/D10,"nm") -> 0.44235145 | Q10: =IF(E10>0,O10/E10,"nm") -> 2.5287082 | R10: =IF(F10>0,O10/F10,"nm") -> 5.3833826 | S10: =IF(G10>0,M10/G10,"nm") -> 10.70086 | T10: =E10/D10 -> 0.17493179
A11: KSHB | B11: Kosambi Housing Finance Ltd | C11: Financials | D11: 10773 | E11: 3178 | F11: 2799 | G11: 1896 | H11: 129.64 | I11: 182.4815 | J11: 4510 | K11: 7153 | L11: 0.13 | M11: =H11*I11 -> 23656.902 | N11: =J11-K11 -> -2643 | O11: =M11+N11 -> 21013.902 | P11: =IF(D11>0,O11/D11,"nm") -> 1.9506082 | Q11: =IF(E11>0,O11/E11,"nm") -> 6.6123039 | R11: =IF(F11>0,O11/F11,"nm") -> 7.5076462 | S11: =IF(G11>0,M11/G11,"nm") -> 12.477269 | T11: =E11/D11 -> 0.29499675
A12: STNM | B12: Stonemark Bancorp | C12: Financials | D12: 17547 | E12: 5177 | F12: 4488 | G12: 3377 | H12: 1016.63 | I12: 51.7056 | J12: 3685 | K12: 16180 | L12: 0.085 | M12: =H12*I12 -> 52565.464 | N12: =J12-K12 -> -12495 | O12: =M12+N12 -> 40070.464 | P12: =IF(D12>0,O12/D12,"nm") -> 2.2836077 | Q12: =IF(E12>0,O12/E12,"nm") -> 7.7400935 | R12: =IF(F12>0,O12/F12,"nm") -> 8.9283565 | S12: =IF(G12>0,M12/G12,"nm") -> 15.565728 | T12: =E12/D12 -> 0.29503619
A13: ATLB | B13: Atlas Biosciences Inc | C13: Health Care | D13: 9870 | E13: 1431 | F13: 1059 | G13: 565 | H13: 89.67 | I13: 165.837 | J13: 3861 | K13: 3092 | L13: 0.131 | M13: =H13*I13 -> 14870.604 | N13: =J13-K13 -> 769 | O13: =M13+N13 -> 15639.604 | P13: =IF(D13>0,O13/D13,"nm") -> 1.5845597 | Q13: =IF(E13>0,O13/E13,"nm") -> 10.929143 | R13: =IF(F13>0,O13/F13,"nm") -> 14.768276 | S13: =IF(G13>0,M13/G13,"nm") -> 26.319653 | T13: =E13/D13 -> 0.1449848
A14: VNDH | B14: Vindhya Pharma Ltd | C14: Health Care | D14: 10421 | E14: 1511 | F14: 1085 | G14: 676 | H14: 120.47 | I14: 161.8067 | J14: 2266 | K14: 2710 | L14: 0.095 | M14: =H14*I14 -> 19492.853 | N14: =J14-K14 -> -444 | O14: =M14+N14 -> 19048.853 | P14: =IF(D14>0,O14/D14,"nm") -> 1.8279295 | Q14: =IF(E14>0,O14/E14,"nm") -> 12.606786 | R14: =IF(F14>0,O14/F14,"nm") -> 17.556547 | S14: =IF(G14>0,M14/G14,"nm") -> 28.835582 | T14: =E14/D14 -> 0.14499568
A15: HRBR | B15: Harbourline Freight Corp | C15: Industrials | D15: 10435 | E15: 1200 | F15: 703 | G15: 477 | H15: 47.19 | I15: 196.6435 | J15: 1750 | K15: 4555 | L15: 0.054 | M15: =H15*I15 -> 9279.6068 | N15: =J15-K15 -> -2805 | O15: =M15+N15 -> 6474.6068 | P15: =IF(D15>0,O15/D15,"nm") -> 0.62047022 | Q15: =IF(E15>0,O15/E15,"nm") -> 5.3955056 | R15: =IF(F15>0,O15/F15,"nm") -> 9.2099669 | S15: =IF(G15>0,M15/G15,"nm") -> 19.454102 | T15: =E15/D15 -> 0.1149976
A16: TPTI | B16: Taptee Logistics Ltd | C16: Industrials | D16: 6957 | E16: 800 | F16: 438 | G16: 170 | H16: 26.7 | I16: 146.6757 | J16: 2355 | K16: 1432 | L16: 0.048 | M16: =H16*I16 -> 3916.2412 | N16: =J16-K16 -> 923 | O16: =M16+N16 -> 4839.2412 | P16: =IF(D16>0,O16/D16,"nm") -> 0.6955931 | Q16: =IF(E16>0,O16/E16,"nm") -> 6.0490515 | R16: =IF(F16>0,O16/F16,"nm") -> 11.048496 | S16: =IF(G16>0,M16/G16,"nm") -> 23.036713 | T16: =E16/D16 -> 0.11499209
... A24: SRYU | B24: Suryodaya Solar Ltd | C24: Utilities | D24: 3941 | E24: 926 | F24: 515 | G24: 359 | H24: 18.49 | I24: 313.4833 | J24: 1031 | K24: 2045 | L24: 0.009 | M24: =H24*I24 -> 5796.3062 | N24: =J24-K24 -> -1014 | O24: =M24+N24 -> 4782.3062 | P24: =IF(D24>0,O24/D24,"nm") -> 1.2134753 | Q24: =IF(E24>0,O24/E24,"nm") -> 5.1644776 | R24: =IF(F24>0,O24/F24,"nm") -> 9.2860315 | S24: =IF(G24>0,M24/G24,"nm") -> 16.1457 | T24: =E24/D24 -> 0.23496574
A26: Note: a loss-making company shows "nm" for P/E. That is not a formatting
A27: problem - it is the reason EV/EBITDA exists. See ARVT.
A29: SELECTED PEER SET | C29: Chosen for similar sector, size and margin structure. Justify every inclusion AND every exclusion.
A30: Ticker | B30: Company | D30: LTM revenue | E30: LTM EBITDA | L30: Rev growth % | M30: Market cap | O30: Enterprise value | P30: EV/Revenue | Q30: EV/EBITDA | R30: EV/EBIT | S30: P/E | T30: EBITDA margin
A31: BHMT | B31: =INDEX(B$5:B$24,MATCH($A31,$A$5:$A$24,0)) -> Bhima Motors Ltd | D31: =INDEX(D$5:D$24,MATCH($A31,$A$5:$A$24,0)) -> 14186 | E31: =INDEX(E$5:E$24,MATCH($A31,$A$5:$A$24,0)) -> 1915 | L31: =INDEX(L$5:L$24,MATCH($A31,$A$5:$A$24,0)) -> 0.082 | M31: =INDEX(M$5:M$24,MATCH($A31,$A$5:$A$24,0)) -> 14451.06 | O31: =INDEX(O$5:O$24,MATCH($A31,$A$5:$A$24,0)) -> 15274.06 | P31: =INDEX(P$5:P$24,MATCH($A31,$A$5:$A$24,0)) -> 1.0766996 | Q31: =INDEX(Q$5:Q$24,MATCH($A31,$A$5:$A$24,0)) -> 7.9760106 | R31: =INDEX(R$5:R$24,MATCH($A31,$A$5:$A$24,0)) -> 11.004366 | S31: =INDEX(S$5:S$24,MATCH($A31,$A$5:$A$24,0)) -> 23.345816 | T31: =INDEX(T$5:T$24,MATCH($A31,$A$5:$A$24,0)) -> 0.13499225
A32: NLSP | B32: =INDEX(B$5:B$24,MATCH($A32,$A$5:$A$24,0)) -> Nilgiri Spice Foods Ltd | D32: =INDEX(D$5:D$24,MATCH($A32,$A$5:$A$24,0)) -> 14632 | E32: =INDEX(E$5:E$24,MATCH($A32,$A$5:$A$24,0)) -> 1975 | L32: =INDEX(L$5:L$24,MATCH($A32,$A$5:$A$24,0)) -> 0.061 | M32: =INDEX(M$5:M$24,MATCH($A32,$A$5:$A$24,0)) -> 18775.46 | O32: =INDEX(O$5:O$24,MATCH($A32,$A$5:$A$24,0)) -> 22185.46 | P32: =INDEX(P$5:P$24,MATCH($A32,$A$5:$A$24,0)) -> 1.5162288 | Q32: =INDEX(Q$5:Q$24,MATCH($A32,$A$5:$A$24,0)) -> 11.233144 | R32: =INDEX(R$5:R$24,MATCH($A32,$A$5:$A$24,0)) -> 16.348902 | S32: =INDEX(S$5:S$24,MATCH($A32,$A$5:$A$24,0)) -> 32.427391 | T32: =INDEX(T$5:T$24,MATCH($A32,$A$5:$A$24,0)) -> 0.13497813
A33: PLMT | B33: =INDEX(B$5:B$24,MATCH($A33,$A$5:$A$24,0)) -> Palmetto Grocers Inc | D33: =INDEX(D$5:D$24,MATCH($A33,$A$5:$A$24,0)) -> 4666 | E33: =INDEX(E$5:E$24,MATCH($A33,$A$5:$A$24,0)) -> 630 | L33: =INDEX(L$5:L$24,MATCH($A33,$A$5:$A$24,0)) -> 0.065 | M33: =INDEX(M$5:M$24,MATCH($A33,$A$5:$A$24,0)) -> 4392.0551 | O33: =INDEX(O$5:O$24,MATCH($A33,$A$5:$A$24,0)) -> 6053.0551 | P33: =INDEX(P$5:P$24,MATCH($A33,$A$5:$A$24,0)) -> 1.2972686 | Q33: =INDEX(Q$5:Q$24,MATCH($A33,$A$5:$A$24,0)) -> 9.608024 | R33: =INDEX(R$5:R$24,MATCH($A33,$A$5:$A$24,0)) -> 14.076872 | S33: =INDEX(S$5:S$24,MATCH($A33,$A$5:$A$24,0)) -> 31.371822 | T33: =INDEX(T$5:T$24,MATCH($A33,$A$5:$A$24,0)) -> 0.13501929
A34: HRBR | B34: =INDEX(B$5:B$24,MATCH($A34,$A$5:$A$24,0)) -> Harbourline Freight Corp | D34: =INDEX(D$5:D$24,MATCH($A34,$A$5:$A$24,0)) -> 10435 | E34: =INDEX(E$5:E$24,MATCH($A34,$A$5:$A$24,0)) -> 1200 | L34: =INDEX(L$5:L$24,MATCH($A34,$A$5:$A$24,0)) -> 0.054 | M34: =INDEX(M$5:M$24,MATCH($A34,$A$5:$A$24,0)) -> 9279.6068 | O34: =INDEX(O$5:O$24,MATCH($A34,$A$5:$A$24,0)) -> 6474.6068 | P34: =INDEX(P$5:P$24,MATCH($A34,$A$5:$A$24,0)) -> 0.62047022 | Q34: =INDEX(Q$5:Q$24,MATCH($A34,$A$5:$A$24,0)) -> 5.3955056 | R34: =INDEX(R$5:R$24,MATCH($A34,$A$5:$A$24,0)) -> 9.2099669 | S34: =INDEX(S$5:S$24,MATCH($A34,$A$5:$A$24,0)) -> 19.454102 | T34: =INDEX(T$5:T$24,MATCH($A34,$A$5:$A$24,0)) -> 0.1149976
A35: TPTI | B35: =INDEX(B$5:B$24,MATCH($A35,$A$5:$A$24,0)) -> Taptee Logistics Ltd | D35: =INDEX(D$5:D$24,MATCH($A35,$A$5:$A$24,0)) -> 6957 | E35: =INDEX(E$5:E$24,MATCH($A35,$A$5:$A$24,0)) -> 800 | L35: =INDEX(L$5:L$24,MATCH($A35,$A$5:$A$24,0)) -> 0.048 | M35: =INDEX(M$5:M$24,MATCH($A35,$A$5:$A$24,0)) -> 3916.2412 | O35: =INDEX(O$5:O$24,MATCH($A35,$A$5:$A$24,0)) -> 4839.2412 | P35: =INDEX(P$5:P$24,MATCH($A35,$A$5:$A$24,0)) -> 0.6955931 | Q35: =INDEX(Q$5:Q$24,MATCH($A35,$A$5:$A$24,0)) -> 6.0490515 | R35: =INDEX(R$5:R$24,MATCH($A35,$A$5:$A$24,0)) -> 11.048496 | S35: =INDEX(S$5:S$24,MATCH($A35,$A$5:$A$24,0)) -> 23.036713 | T35: =INDEX(T$5:T$24,MATCH($A35,$A$5:$A$24,0)) -> 0.11499209
A36: Median | P36: =MEDIAN(P31:P35) -> 1.0766996 | Q36: =MEDIAN(Q31:Q35) -> 7.9760106 | R36: =MEDIAN(R31:R35) -> 11.048496 | S36: =MEDIAN(S31:S35) -> 23.345816
A37: Mean | P37: =AVERAGE(P31:P35) -> 1.0412521 | Q37: =AVERAGE(Q31:Q35) -> 8.0523472 | R37: =AVERAGE(R31:R35) -> 12.337721 | S37: =AVERAGE(S31:S35) -> 25.927169
A38: Minimum | P38: =MIN(P31:P35) -> 0.62047022 | Q38: =MIN(Q31:Q35) -> 5.3955056 | R38: =MIN(R31:R35) -> 9.2099669 | S38: =MIN(S31:S35) -> 19.454102
A39: Maximum | P39: =MAX(P31:P35) -> 1.5162288 | Q39: =MAX(Q31:Q35) -> 11.233144 | R39: =MAX(R31:R35) -> 16.348902 | S39: =MAX(S31:S35) -> 32.427391
A40: Lower quartile | P40: =QUARTILE(P31:P35,1) -> 0.6955931 | Q40: =QUARTILE(Q31:Q35,1) -> 6.0490515 | R40: =QUARTILE(R31:R35,1) -> 11.004366 | S40: =QUARTILE(S31:S35,1) -> 23.036713
A41: Upper quartile | P41: =QUARTILE(P31:P35,3) -> 1.2972686 | Q41: =QUARTILE(Q31:Q35,3) -> 9.608024 | R41: =QUARTILE(R31:R35,3) -> 14.076872 | S41: =QUARTILE(S31:S35,3) -> 31.371822
A43: IMPLIED VALUE OF KVRA AT THE PEER MEDIAN
A44: Peer median EV/EBITDA | D44: =Q36 -> 7.9760106
A45: KVRA LTM EBITDA | D45: =E7 -> 1243
A46: Implied enterprise value | D46: =D44*D45 -> 9914.1812
A47: Less: net debt | D47: =-N7 -> 1249
A48: Implied equity value | D48: =D46+D47 -> 11163.181
A49: Implied value per share (Rs) | D49: =D48/H7 -> 128.06219
A50: Current share price (Rs) | D50: =I7 -> 149.6865
A51: Upside / (downside) | D51: =D49/D50-1 -> -0.14446399
